Workbook

Sheet Instructions
A1: Pilot v3 QA review
A3: What to do
A4: 1. On the Review sheet, the top 20 rows (priority = TRUE, shaded) are a stratified sample: 5 filter-rejected pairs, 5 repaired pairs, and 10 other passed pairs across question types. Review those (about 20 minutes).
A5: 2. Pick accept or reject in human_verdict (yellow, dropdown). If rejecting, pick a reject_category and add a short note.
A6: 3. Review BLIND first. The last three columns (claude_verdict, claude_category, claude_note) hold Claude's pre-screen and are collapsed. Expand them (the + above them) only after you finish your 20 rows, then compare.
A7: 4. The Agreement sheet updates automatically: you vs the automatic filters, and you vs Claude's pre-screen.
A9: Accept a pair only if all three are true
A10: Correct: the answer is fully supported by the evidence, with nothing added.
A11: Standalone: the question makes sense to someone who has never seen the source.
A12: Worth learning: it is about the domain (responsible AI, higher education), not trivia, study methodology or bibliography.
A14: Reject categories
A15: incorrect - answer contradicts or misreads the evidence
... A23: Save (keep .xlsx), copy into the project as data/qa_pairs/pilot_review_v3_reviewed.xlsx, and ask Claude Code to merge human_verdict, reject_category and human_notes by qa_id (sheet "Review").

Sheet Review
A1: # | B1: priority | C1: human_verdict | D1: reject_category | E1: human_notes | F1: question | G1: answer | H1: evidence | I1: citation | J1: passed_filters | K1: repaired | L1: reject_reason | M1: q_type | N1: difficulty | O1: dimension | P1: grounding | Q1: value | R1: judge_rationale | S1: paraphrase_1 | T1: paraphrase_2 | U1: origin | V1: qa_id | W1: claude_verdict | X1: claude_category | Y1: claude_note
A2: 1 | B2: =TRUE() -> TRUE | F2: Why is the concentration of top-ranked universities in a few regions of the world not simply a matter of the best institutions naturally rising to the top? | G2: Scholars of educational, health or other inequalities have long noted that underlying structures invariably create, maintain and often exacerbate social inequalities. In other words, it is not about the cream rising to the top, but about a system in which the cream identifies itself as better and uses systemic processes to stay there. | H2: Scholars of educational, health, or other inequalities, though, have long noted that underlying structures invariably create, maintain and often exacerbate social inequalities. In other words, it is not about the cream rising to the top, but rather about the presence of a system in which the cream identifies itself as better and utilises systemic processes to stay there. | I2: Socially Responsible Higher Education, p. 96 | J2: =TRUE() -> TRUE | K2: =TRUE() -> TRUE | M2: explanation | N2: medium | O2: equity_accessibility | P2: 5 | Q2: 4 | R2: The answer restates the quoted evidence almost verbatim, with only trivial rewording. The evidence does not itself mention regional concentration of rankings, but the answer makes no claim about it. | The question is self-contained and does not refer to any unseen source or context. | value: It covers a useful critical perspective on structural inequality in global university rankings. | S2: Why is the dominance of a few regions in world university rankings not just a case of merit naturally rising? | T2: Why can the dominance of a handful of world regions among top-ranked universities not be explained merely by the best institutions naturally ascending to the top? | U2: pilot | V2: budd-l-hall-rajesh-2021-socially-responsible:0055:q2 | W2: accept | Y2: Non-AI content (Socially Responsible HE book); these chunks have ai_score=0 and are excluded from full_v1 anyway.
A3: 2 | B3: =TRUE() -> TRUE | F3: What technique conceals confidential information in a way that does not affect the overall outcome of an AI system's decision-making process? | G3: Data masking is the technique in which confidential information is concealed in a way that does not affect the overall outcome of the decision-making process. | H3: This can be achieved through techniques such as data masking, where confidential information is concealed in a way that does not affect the overall outcome of the decisionmaking process. | I3: Towards Ethical and Socially Responsible Explainable AI, p. 103 | J3: =TRUE() -> TRUE | K3: =TRUE() -> TRUE | M3: factual | N3: easy | O3: privacy_security | P3: 5 | Q3: 4 | R3: The answer restates the evidence almost verbatim: data masking conceals confidential information without affecting the overall outcome of decision-making. | The question names the concept (concealing confidential information in AI decision-making) without referring to an unseen source. | value: Data masking is a useful privacy-preserving technique relevant to responsible AI. | S3: Which technique hides confidential data without changing the overall outcome of an AI system's decision-making? | T3: Which approach hides sensitive information within an AI system without changing the final result of its decision-making? | U3: pilot | V3: towards-ethical:0051:q2 | W3: accept
A4: 3 | B4: =TRUE() -> TRUE | F4: In ethical explainable AI, what does it mean for an AI system to be transparent and auditable? | G4: Transparency requires clear and understandable explanations of the system's decision-making processes, the data used, and the outcomes produced. Being auditable means that the decision-making processes can be traced and verified by relevant parties. | H4: This requires clear and understandable explanations of the decision-making processes, the data used, and the outcomes produced by the system. It also requires ensuring that the system is auditable, meaning that the decision-making processes can be traced and verified by relevant parties [9]. | I4: Towards Ethical and Socially Responsible Explainable AI, p. 104 | J4: =TRUE() -> TRUE | K4: =TRUE() -> TRUE | M4: definition | N4: medium | O4: governance | P4: 4 | Q4: 4 | R4: The answer closely restates the evidence. However, the evidence refers only to "this", so tying the explanation requirement specifically to transparency is a slight assumption. | The question is self-contained and clearly names the concepts it asks about. | value: Transparency and auditability are useful core concepts in responsible AI. | S4: What do transparency and auditability require of an AI system in ethical explainable AI? | T4: In ethical explainable AI, what must be in place for an AI system to count as transparent and as auditable? | U4: pilot | V4: towards-ethical:0051:q4 | W4: accept
A5: 4 | B5: =TRUE() -> TRUE | F5: A university is deploying an AI admissions-screening tool that processes applicants' personal data and affects individuals' lives. What accountability practices on data privacy and algorithmic bias apply? | G5: The organization should adhere to data privacy laws such as the GDPR in the European Union or the CCPA in the United States, implementing robust data protection measures, obtaining necessary consents, and enabling users to exercise their privacy rights. It should also implement measures to identify and mitigate algorithmic bias, particularly in applications that affect individuals' lives such as hiring or lending decisions, and regularly audit algorithms for fairness. | H5: Data Privacy Compliance: Adhere to data privacy laws such as the General Data Protection Regulation (GDPR) in the European Union or the California Consumer Privacy Act (CCPA) in the United States [31]. Implement robust data protection measures, obtain necessary consents, and enable users to exercise their privacy rights. … Algorithmic Bias Mitigation: Implement measures to identify and mitigate algorithmic bias, particularly in applications that impact individuals' lives, such as hiring or lending decisions. Regularly audit algorithms for fairness. | I5: Towards Ethical and Socially Responsible Explainable AI, pp. 171-172 | J5: =TRUE() -> TRUE | K5: =FALSE() -> FALSE | M5: application | N5: hard | O5: privacy_security | P5: 4 | Q5: 4 | R5: The answer restates the evidence nearly verbatim. Applying general guidance to a university admissions scenario is a mild framing, but the answer itself adds no unsupported claims. | The scenario is self-contained and uses no source references. Acronyms appear only in the answer. | value: These are useful accountability practices on privacy and bias for AI deployment. | S5: A university plans to use an AI tool to screen admissions applications using personal data, with consequences for people's lives. Which data privacy and bias-related accountability practices should it follow? | T5: A university is rolling out an AI tool to screen admissions applications, which handles applicants' personal data and influences their lives. Which accountability practices relating to data privacy and algorithmic bias are relevant? | U5: pilot | V5: towards-ethical:0090:q0 | W5: accept
A6: 5 | B6: =TRUE() -> TRUE | F6: Which regulation should healthcare AI systems comply with as an example of sector-specific regulation? | G6: Healthcare AI systems should comply with Health Insurance Portability and Accountability Act (HIPAA) regulations. Organizations should be aware of sector-specific regulations that may apply to AI applications. | H6: Sector-Specific Regulations: Be aware of sector-specific regulations that may apply to AI applications. For instance, healthcare AI systems should comply with Health Insurance Portability and Accountability Act (HIPAA) regulations. | I6: Towards Ethical and Socially Responsible Explainable AI, p. 172 | J6: =TRUE() -> TRUE | K6: =FALSE() -> FALSE | M6: factual | N6: easy | O6: privacy_security | P6: 5 | Q6: 3 | R6: Both statements are directly stated in the evidence: be aware of sector-specific regulations, and healthcare AI should comply with HIPAA. | The question is self-contained and needs no reference to an unseen source. | value: This is a basic compliance example that is only tangential to AI in higher education. | S6: As an example of a sector-specific rule for AI, which regulations must healthcare AI systems comply with? | T6: As an instance of sector-specific regulation, which law must AI systems used in healthcare comply with? | U6: pilot | V6: towards-ethical:0090:q4 | W6: accept
A7: 6 | B7: =TRUE() -> TRUE | F7: A nursing school wants to roll out generative AI for assessment generation and clinical simulation while keeping students' trust and the school's standards intact. What do the 2025 PAGER scoping review's recommendations on ChatGPT in nursing education say it should do? | G7: Implementation should follow evidence-based approaches in assessment generation and clinical simulation development, aligning with established pedagogical frameworks to enhance rather than replace effective teaching practices. Nursing education also needs a comprehensive framework that balances innovation with academic integrity in assessment and clinical training, sets clear data privacy and security standards, and ensures compliance with educational regulations. Developing technical and ethical competencies is crucial, especially for upholding academic integrity and ensuring equitable student access. | H7: Implementation should follow evidence-based approaches in assessment generation and clinical simulation development, aligning with established pedagogical frameworks to enhance rather than replace effective teaching practices. … The findings indicate the necessity of establishing a comprehensive system that balances innovation with academic integrity in nursing assessment and clinical training. These frameworks should establish clear data privacy and security standards guidelines and ensure compliance with educational regulations (Foronda and Porter, 2024). … Systematic documentation and evaluation of implementation experiences will contribute to developing best practices. Developing technical and ethical competencies is crucial, especially for upholding academic integrity and ensuring equitable student access. Cross-institutional collaboration should be encouraged to share implementation strategies and lessons learned. | I7: Patterns, advances, and gaps in using ChatGPT and similar technologies in nursing education: A PAGER scoping review, p. 8 | J7: =TRUE() -> TRUE | K7: =FALSE() -> FALSE | M7: application | N7: hard | O7: teaching_learning | P7: 4 | Q7: 4 | R7: The answer closely restates the evidence. The only changes are trivial rewordings, such as "framework" for "system". | The question identifies the source by its content (a 2025 PAGER scoping review on ChatGPT in nursing education) and sets out a clear scenario. | value: These are practical, domain-relevant recommendations for responsibly implementing generative AI in nursing education. | S7: If a nursing school introduces generative AI for assessment generation and clinical simulation, what approach does the PAGER scoping review on nursing education recommend it take? | T7: A school of nursing intends to introduce generative AI to generate assessments and run clinical simulations, while preserving student trust and its own standards. What steps does the 2025 PAGER scoping review on ChatGPT in nursing education advise it to take? | U7: pilot | V7: patterns-advances-and-gaps-in-using-chatgpt-and:0016:q0 | W7: accept
A8: 7 | B8: =TRUE() -> TRUE | F8: According to a PAGER scoping review of ChatGPT and similar technologies in nursing education, why should nursing curricula pair content on critical thinking with ethical guidelines? | G8: Authors emphasise the need for content that develops critical thinking abilities alongside the establishment of ethical guidelines in order to ensure responsible AI use. | H8: Building on this foundation, authors emphasise the need for content that develops critical thinking abilities alongside the establishment of ethical guidelines to ensure responsible AI use (Alkhaqani, 2023b; Archibald and Clark, 2023; Athilingam and He, 2024). | I8: Patterns, advances, and gaps in using ChatGPT and similar technologies in nursing education: A PAGER scoping review, p. 7 | J8: =TRUE() -> TRUE | K8: =FALSE() -> FALSE | M8: explanation | N8: medium | O8: student_ai_literacy | P8: 5 | Q8: 4 | R8: The answer restates the evidence nearly verbatim: content developing critical thinking alongside ethical guidelines is needed to ensure responsible AI use. | The question names the specific review by its content (a PAGER scoping review of ChatGPT in nursing education). The phrase 'according to' does presuppose a source, but here it identifies a named work, which is acceptable. | value: A useful curricular recommendation for responsible AI use in nursing education. | S8: In the PAGER scoping review on GenAI in nursing education, what is the purpose of developing critical thinking abilities alongside ethical guidelines in nursing content? | T8: Why does the PAGER scoping review of GenAI in nursing education call for nursing content that builds critical thinking together with ethical guidelines? | U8: pilot | V8: patterns-advances-and-gaps-in-using-chatgpt-and:0013:q0 | W8: accept
A9: 8 | B9: =TRUE() -> TRUE | F9: What technical improvements to GenAI do nursing education studies recommend in the PAGER scoping review? | G9: Technical recommendations focus on improving GenAI's accuracy and reducing bias by refining models to better reflect nursing standards and classification systems. | H9: Technical recommendations focus on improving GenAI's accuracy and reducing bias by refining models to reflect nursing standards and classification systems better (Gosak et al., 2024; Ye, 2024). | I9: Patterns, advances, and gaps in using ChatGPT and similar technologies in nursing education: A PAGER scoping review, p. 7 | J9: =TRUE() -> TRUE | K9: =FALSE() -> FALSE | M9: factual | N9: easy | O9: procurement_technology | P9: 5 | Q9: 4 | R9: The answer restates the evidence almost verbatim; every claim (accuracy, bias reduction, refining models to reflect nursing standards and classification systems) is directly stated. | The question names the PAGER scoping review and the topic, GenAI in nursing education, and does not refer to unseen context. PAGER is a named framework, so the question is acceptable as it stands. | value: These are useful, fairly specific recommendations about GenAI accuracy and bias in nursing education. | S9: Which technical recommendations for GenAI in nursing education are made in the PAGER scoping review? | T9: In the PAGER scoping review of GenAI in nursing education, what do technical recommendations focus on? | U9: pilot | V9: patterns-advances-and-gaps-in-using-chatgpt-and:0013:q2 | W9: accept
A10: 9 | B10: =TRUE() -> TRUE | F10: How do AI-driven entrepreneurial simulation systems improve students' ability to handle complex business scenarios? | G10: These simulation systems let students practice entrepreneurial decision-making in a low-risk environment and give them instant feedback, which improves their ability to handle complex business scenarios. | H10: For instance, AI-driven entrepreneurial simulation systems enable students to practice entrepreneurial decision-making in a low-risk environment, providing instant feedback and improving their ability to handle complex business scenarios (Chen et al., 2022; Mavlutova et al., 2020; Nowak, 2020). | I10: Toward understanding the role of generative AI in entrepreneurship education: A systematic review, p. 14 | J10: =TRUE() -> TRUE | K10: =FALSE() -> FALSE | M10: explanation | N10: medium | O10: teaching_learning | P10: 5 | Q10: 4 | R10: The answer directly restates the evidence: practice in a low-risk environment, instant feedback, and improved handling of complex scenarios. | The question names the technology by its content and does not refer to any unseen source. | value: This is useful and somewhat specific knowledge about how AI is applied in entrepreneurship education. | S10: Why do AI-driven entrepreneurial simulation systems help students deal better with complex business scenarios? | T10: By what means do AI-driven entrepreneurial simulations strengthen students' handling of complex business scenarios? | U10: pilot | V10: toward-understanding-the-role-of-generative-ai:0024:q2 | W10: accept
A11: 10 | B11: =TRUE() -> TRUE | F11: What shift in AI-powered learning models in entrepreneurship education has been observed, and what benefit may it bring? | G11: AI-powered learning models in entrepreneurship education are shifting from traditional static courses toward more personalized, immersive, and data-driven approaches. This may contribute to improved student learning experiences and knowledge acquisition. | H11: AIpowered learning models in EE are increasingly shifting from traditional static courses toward more personalized, immersive, and datadriven approaches, which may contribute to improved student learning experiences and knowledge acquisition. | I11: Toward understanding the role of generative AI in entrepreneurship education: A systematic review, p. 14 | J11: =TRUE() -> TRUE | K11: =FALSE() -> FALSE | M11: definition | N11: medium | O11: teaching_learning | P11: 5 | Q11: 4 | R11: The answer restates the evidence almost verbatim, covering both the shift toward personalized, immersive, data-driven approaches and the potential benefit. It adds nothing beyond what the evidence says. | The question names its topic, AI-powered learning models in entrepreneurship education, explicitly and does not refer to any unseen source. | value: This is useful domain knowledge about how AI is changing pedagogy in one specific field of higher education. | S11: How are AI-powered learning models in entrepreneurship education changing compared with traditional courses, and what may this improve? | T11: What change is occurring in entrepreneurship education learning models powered by AI, and what outcomes might it contribute to? | U11: pilot | V11: toward-understanding-the-role-of-generative-ai:0024:q3 | W11: accept
A12: 11 | B12: =TRUE() -> TRUE | F12: How might cultural and contextual settings affect the effectiveness of generative-AI-enabled entrepreneurship education, and which macro-level factors are proposed as influences? | G12: The effectiveness of generative-AI-enabled entrepreneurship education is proposed to vary across cultural and contextual settings. This variation is influenced by macro-level factors such as government support, economic conditions, and cultural norms. | H12: Research Proposition 2: The effectiveness of GAI-enabled EE varies across cultural and contextual settings, influenced by macro-level factors such as government support, economic conditions, and cultural norms. Future research could apply HLM and Hofstede's Cultural Dimensions Theory to examine how uncertainty avoidance, collectivism, and digital infrastructure moderate learners' trust in GAI and their collaborative behaviors. | I12: Toward understanding the role of generative AI in entrepreneurship education: A systematic review, p. 19 | J12: =TRUE() -> TRUE | K12: =TRUE() -> TRUE | M12: explanation | N12: medium | O12: equity_accessibility | P12: 5 | Q12: 4 | R12: The answer directly restates Research Proposition 2, including the three macro-level factors named in the evidence. | The question names its topic by content and has no source references or undefined acronyms. | value: This is a useful proposition about contextual influences on AI-enabled entrepreneurship education, though somewhat specific. | S12: In what way could cultural and contextual settings change how effective generative-AI-enabled entrepreneurship education is, and which macro-level factors are proposed to influence it? | T12: Which macro-level factors are proposed to make the effectiveness of generative-AI-enabled entrepreneurship education vary across cultural and contextual settings? | U12: pilot | V12: toward-understanding-the-role-of-generative-ai:0033:q4 | W12: accept
A13: 12 | B13: =TRUE() -> TRUE | F13: What does the AI competency work of Celik (2023) do with the TPACK model, and what is its purpose? | G13: Celik (2023) extended the TPACK model to include AI competencies for teacher development. | H13: Celik (2023) extended the TPACK model to include AI competencies for teacher development, while Long and Magerko (2020) focusing on K-12 and Carolus et al. (2023) focusing on citizens' competencies, using literature reviews to shape their frameworks. | I13: Be AIware! An AI Competency Model for K-12 Education, p. 3 | J13: =TRUE() -> TRUE | K13: =FALSE() -> FALSE | M13: definition | N13: medium | O13: faculty_readiness | P13: 5 | Q13: 4 | R13: The answer directly restates the evidence that Celik (2023) extended TPACK to include AI competencies for teacher development. | The question names a specific study (Celik 2023) and a named model, and it does not refer to unseen context. TPACK is a widely known acronym in educational technology. | value: It is useful domain knowledge about an AI competency framework for teacher development. | S13: How did Celik (2023) extend the TPACK model, and for what purpose? | T13: What addition did Celik (2023) make to the TPACK model, and what was it meant to support? | U13: pilot | V13: be-aiware-an-ai-competency-model-for-k-12:0004:q1 | W13: accept
A14: 13 | B14: =TRUE() -> TRUE | F14: Why must general claims of AI grading efficacy be tempered by task-specific evaluation? | G14: AI grading performance varies by task type, discipline, and contextual alignment with assessment rubrics. Because of this variation, general claims of AI efficacy must be tempered by task-specific evaluation. AI performs reliably in structured tasks, but its accuracy declines in open-ended or creative assignments that require nuanced contextual understanding. | H14: Empirical evidence indicates that AI grading performance varies by task type, discipline, and contextual alignment with assessment rubrics, suggesting that general claims of AI efficacy must be tempered by task-specific evaluation (Condor, 2024). … While AI performs reliably in structured tasks, its accuracy declines in openended or creative assignments, where nuanced contextual understanding is required (Lo et al., 2025). | I14: Reliable but not rigorous: Evaluating ChatGPT's reliability, validity, and bias in automated academic grading, p. 2 | J14: =TRUE() -> TRUE | K14: =TRUE() -> TRUE | M14: explanation | N14: medium | O14: assessment | P14: 4 | Q14: 4 | R14: Every statement is supported by the evidence. The answer only lightly rewords the source and adds a causal link that the evidence's "suggesting that" already implies. | The question is self-contained and clear without needing the source. | value: This is useful knowledge about the limits of AI grading reliability in assessment. | S14: Why should broad claims that AI grading works be qualified by evaluating specific tasks? | T14: What reason is there for qualifying general claims about the efficacy of AI grading through task-specific evaluation? | U14: extra:assessment | V14: reliable-but-not-rigorous-evaluating-chatgpt-s:0002:q3 | W14: accept
A15: 14 | B15: =TRUE() -> TRUE | F15: Why does a lack of comprehensive frameworks for preparing faculty for AI matter for higher education institutions? | G15: Many higher education institutions lack comprehensive frameworks to prepare faculty for emerging technological challenges such as AI. This gap undermines their ability to integrate AI into teaching, research, and service, thereby constraining institutional responsiveness to societal needs. | H15: Despite their strategic role, many HEIs lack comprehensive frameworks to prepare faculty for emerging technological challenges such as artificial intelligence. This gap undermines their ability to integrate AI into teaching, research, and service, thereby constraining institutional responsiveness to societal needs (Sued, 2022). | I15: Stakeholder engagement and strategic innovation in higher education through AI competency, p. 4 | J15: =TRUE() -> TRUE | K15: =FALSE() -> FALSE | M15: explanation | N15: medium | O15: faculty_readiness | P15: 5 | Q15: 4 | R15: Both sentences of the answer restate the evidence almost word for word. Nothing is added. | The question is self-contained and does not refer to any source or unseen context. | value: It covers a relevant institutional point about faculty AI readiness and its consequences. | S15: What are the consequences for universities when they lack comprehensive frameworks to prepare faculty for AI? | T15: How does the absence of comprehensive faculty AI-preparation frameworks affect higher education institutions? | U15: extra:leadership_strategy | V15: stakeholder-engagement-and-strategic-innovation:0006:q3 | W15: accept
A16: 15 | B16: =TRUE() -> TRUE | F16: Why should faculty development be integrated as a governance strategy in higher education institutions? | G16: Recognition of faculty as agents of transformation must be translated into capacity-building initiatives and resource allocation that enable faculty to act effectively. When integrated as a governance strategy, faculty development strengthens institutional capacity to address external challenges and contributes to broader societal and economic goals. | H16: In the context of AI, this recognition must be translated into capacity-building initiatives and resource allocation that enable faculty to act effectively. Faculty development, when integrated as a governance strategy, strengthens institutional capacity to address external challenges and contributes to broader societal and economic goals (Syed et al., 2024). | I16: Stakeholder engagement and strategic innovation in higher education through AI competency, p. 4 | J16: =TRUE() -> TRUE | K16: =FALSE() -> FALSE | M16: explanation | N16: medium | O16: governance | P16: 4 | Q16: 4 | R16: The evidence supports the answer. The answer only adds "of faculty as agents of transformation" to define the recognition, which the evidence implies but does not quote. It also drops the "in the context of AI" qualifier. | The question is clear without the source and does not refer to any unseen context. | value: This is a useful institutional governance point about building faculty capacity for AI. | S16: How does treating faculty development as a governance strategy benefit universities? | T16: What is the benefit of integrating faculty development into the governance of higher education institutions? | U16: extra:leadership_strategy | V16: stakeholder-engagement-and-strategic-innovation:0006:q4 | W16: accept
A17: 16 | B17: =TRUE() -> TRUE | F17: In Peruvian law schools, what function do free legal aid clinics often serve for students? | G17: Free legal aid clinics often function as alternatives to internships, where students can get educational credit and recognition for internship work. This was the case in 27 institutions. | H17: First, it is interesting to note that of the 31 institutions surveyed, only 3 have implemented public interest clinics, while the remainder have opted for free legal aid clinics. The latter often function as alternatives to internships, where students can get educational credit and recognition for internship work (27 institutions). | I17: Socially Responsible Higher Education, p. 222 | J17: =FALSE() -> FALSE | K17: =FALSE() -> FALSE | L17: low_value(2) | M17: definition | N17: easy | O17: teaching_learning | P17: 5 | Q17: 2 | R17: Every statement in the answer is directly stated in the evidence. This includes the alternative-to-internship function, the educational credit and recognition, and the figure of 27 institutions. | The question names its context (Peruvian law schools, free legal aid clinics) and does not rely on any unseen source. | value: This is a narrow detail about Peruvian legal clinical education, with no connection to AI or responsible AI. | S17: What role do free legal aid clinics often play for students at Peruvian law schools? | T17: How do Peruvian law students often use free legal aid clinics in relation to internships? | U17: pilot | V17: budd-l-hall-rajesh-2021-socially-responsible:0120:q2 | W17: reject | X17: low_value | Y17: Agree with filter (low value).
A18: 17 | B18: =TRUE() -> TRUE | F18: Which areas of law do Peruvian free legal aid clinics cover most, and how many of 31 clinics deal with civil law? | G18: Of the 31 clinics, 24 provided services in family law and 16 provided representation in criminal law cases. Only 15 indicated that they deal with civil law cases, an unusual number given that civil law is the most common area of practice in Peru. | H18: Out of the 31 clinics, 24 free legal aid clinics provided services in family law and 16 provided representation in criminal law cases. Surprisingly, only 15 of the clinics indicated that they deal with civil law cases - an unusual number given that civil law is the most common area of practice in Peru. | I18: Socially Responsible Higher Education, p. 223 | J18: =FALSE() -> FALSE | K18: =FALSE() -> FALSE | L18: not_standalone(judge);low_value(2) | M18: factual | N18: easy | O18: general | P18: 5 | Q18: 2 | R18: Every figure and the remark about civil law being Peru's most common area of practice are stated directly in the evidence. | The question refers to a specific sample of 31 clinics without naming the survey or study it comes from, so it presupposes unseen context. | value: These are sample-specific survey counts about Peruvian legal aid clinics, unrelated to responsible AI. | S18: Among 31 Peruvian free legal aid clinics, which legal areas are most common, and how many handle civil law cases? | T18: What areas of law do most Peruvian free legal aid clinics serve, and how many of the 31 take civil law cases? | U18: pilot | V18: budd-l-hall-rajesh-2021-socially-responsible:0120:q4 | W18: reject | X18: low_value | Y18: Agree with filter (low value).
A19: 18 | B19: =TRUE() -> TRUE | F19: According to a 2017 ENARSU Network study of 50 Peruvian universities, what share considered social responsibility in higher education a central pillar of their institution? | G19: Only 43% of the 50 universities surveyed considered social responsibility in higher education a central pillar in their institution. The same report found that only 36% were incorporating it into curriculums and campus life. | H19: In line with this finding, a 2017 study by Peru's ENARSU Network (Network of the National Meeting on Social Responsibility in Higher Education) found that only 43% of the 50 universities surveyed considered SRHEI as a central pillar in their institution (Stojnic Chávez & Jungbluth Melgar, 2017, p. 4). This last report also found that only 36% of universities studied were incorporating SRHEI into curriculums and campus life (Stojnic Chávez & Jungbluth Melgar, 2017, pp. 5-6). | I19: Socially Responsible Higher Education, p. 220 | J19: =FALSE() -> FALSE | K19: =FALSE() -> FALSE | L19: low_value(2) | M19: factual | N19: easy | O19: monitoring_improvement | P19: 5 | Q19: 2 | R19: Both the 43% figure and the 36% curriculum and campus-life figure are directly stated in the evidence. | The question names the specific study by year, network and sample, so it is clear without the source; ENARSU works as a proper name. | value: A single regional survey statistic on university social responsibility, only tangentially about AI in higher education. | S19: In the 2017 ENARSU Network survey of 50 Peruvian universities, what percentage treated social responsibility in higher education as a central pillar? | T19: What proportion of the 50 Peruvian universities surveyed by the ENARSU Network in 2017 regarded social responsibility in higher education as a central institutional pillar? | U19: pilot | V19: budd-l-hall-rajesh-2021-socially-responsible:0118:q1 | W19: reject | X19: low_value | Y19: Agree with filter (low value).
A20: 19 | B20: =TRUE() -> TRUE | F20: Which kinds of earlier, pre-2022 studies were considered eligible in a review of generative AI in entrepreneurship education? | G20: Earlier studies were eligible if they focused on algorithmic foundations, prototype generative systems, or theoretical frameworks directly relevant to the functionalities later embodied in generative tools. This applied particularly to those published prior to 2022, before the public release of large-scale GAI platforms such as ChatGPT and DALL-E. | H20: Earlier studies that focused on algorithmic foundations, prototype generative systems, or theoretical frameworks directly relevant to the functionalities later embodied in generative tools were considered eligible for inclusion particularly those published prior to 2022, before the public release of large-scale GAI platforms such as ChatGPT and DALL-E. | I20: Toward understanding the role of generative AI in entrepreneurship education: A systematic review, p. 3 | J20: =FALSE() -> FALSE | K20: =FALSE() -> FALSE | L20: low_value(2) | M20: definition | N20: medium | O20: general | P20: 5 | Q20: 2 | R20: The answer restates the evidence nearly verbatim: the three study types, the pre-2022 timing, and the reference to ChatGPT and DALL-E. | The question names the review by its topic (generative AI in entrepreneurship education), which is acceptable, and it uses no source-dependent wording. | value: This covers review inclusion criteria, which is research methodology and of low domain value. | S20: What types of studies published before 2022 counted as eligible in a review of generative AI in entrepreneurship education? | T20: In a review on generative AI in entrepreneurship education, which earlier studies were eligible for inclusion? | U20: pilot | V20: toward-understanding-the-role-of-generative-ai:0005:q2 | W20: reject | X20: low_value | Y20: Agree with filter (low value).
A21: 20 | B21: =TRUE() -> TRUE | F21: What method did Leidig et al. (2020) use to ensure expert consensus on digital competencies for information systems programs? | G21: Leidig et al. (2020) used a Delphi method, ensuring expert consensus on digital competencies for information systems programs. | H21: Ng et al. (2023) addressed post-pandemic education through a literature review, while Leidig et al. (2020) used a Delphi method, ensuring expert consensus on digital competencies for information systems programs. | I21: Be AIware! An AI Competency Model for K-12 Education, p. 3 | J21: =FALSE() -> FALSE | K21: =FALSE() -> FALSE | L21: low_value(2) | M21: factual | N21: easy | O21: general | P21: 5 | Q21: 2 | R21: The answer restates the evidence almost verbatim: Leidig et al. (2020) used a Delphi method to ensure expert consensus. | The question names the specific study by its authors and topic, and it does not refer to any unseen context. | value: The pair concerns the research methodology of a single study, which has low domain value. | S21: How did Leidig et al. (2020) achieve expert consensus on digital competencies for information systems programs? | T21: Which method did Leidig et al. (2020) employ to establish expert agreement on digital competencies for information systems programs? | U21: pilot | V21: be-aiware-an-ai-competency-model-for-k-12:0004:q4 | W21: reject | X21: low_value | Y21: Agree with filter (low value).
A22: 21 | B22: =FALSE() -> FALSE | F22: A ministry of education in Argentina wants to improve inclusion in universities and notes that enrollment has grown steadily. Which inclusion policies has Argentina relied on, and what problem persists among lower-income young people? | G22: Argentina's main inclusion policies in university education have been territorial expansion of offerings and sustained enrollment growth, along with some scholarship and tutoring programmes. Even so, dropout remains high, particularly among young people from lower-income socioeconomic sectors. | H22: One of the main policies of inclusion in the Argentine university system has been the territorial expansion of offerings and the sustained increase in enrollment, along with some scholarship and tutoring programmes for courses. … However, as García de Fanelli (2014, p. 290) points out, levels of abandonment are high, particularly for young people from lower-income socioeconomic sectors, given that "[higher education] is associated with the cultural capital of the family and with the possibilities of young people having access to quality high school education". | I22: Socially Responsible Higher Education, p. 50 | J22: =TRUE() -> TRUE | K22: =FALSE() -> FALSE | M22: application | N22: hard | O22: equity_accessibility | P22: 4 | Q22: 3 | R22: Every claim in the answer matches the evidence: territorial expansion, enrollment growth, scholarships and tutoring, and high dropout among lower-income youth. 'Dropout' is only a trivial rewording of 'abandonment'. | The question sets up its own scenario and names Argentina directly, with no reference to an unseen source. | value: Higher education inclusion policy is relevant context, but the pair covers one country only and is not about AI. | S22: An Argentine education ministry sees steadily rising university enrollment and wants greater inclusion. What main inclusion policies has the country used, and what difficulty remains for young people from lower-income backgrounds? | T22: Suppose Argentine policymakers review university inclusion after years of enrollment growth. Which policies have been the main inclusion tools, and what issue still affects lower-income youth? | U22: pilot | V22: budd-l-hall-rajesh-2021-socially-responsible:0027:q0 | W22: accept | Y22: Non-AI content (Socially Responsible HE book); these chunks have ai_score=0 and are excluded from full_v1 anyway.
A23: 22 | B23: =FALSE() -> FALSE | F23: Why does dropout from Argentine higher education remain high among young people from lower-income sectors? | G23: According to García de Fanelli, higher education is associated with the cultural capital of the family and with the possibilities of young people having access to quality high school education. Because of this, levels of abandonment are high, particularly for young people from lower-income socioeconomic sectors. | H23: However, as García de Fanelli (2014, p. 290) points out, levels of abandonment are high, particularly for young people from lower-income socioeconomic sectors, given that "[higher education] is associated with the cultural capital of the family and with the possibilities of young people having access to quality high school education". | I23: Socially Responsible Higher Education, p. 50 | J23: =TRUE() -> TRUE | K23: =FALSE() -> FALSE | M23: explanation | N23: medium | O23: equity_accessibility | P23: 5 | Q23: 3 | R23: The answer directly restates the evidence's causal explanation (family cultural capital and access to quality high school education) and attributes it to García de Fanelli. | The question is self-contained and clearly asks about the causes of dropout among lower-income youth in Argentine higher education. | value: It concerns the institutional equity context of higher education but is narrow and not about AI. | S23: Why do lower-income young people in Argentina continue to drop out of higher education at high levels? | T23: What accounts for the continued high dropout rates in Argentine higher education among young people from lower-income sectors? | U23: pilot | V23: budd-l-hall-rajesh-2021-socially-responsible:0027:q1 | W23: accept | Y23: Non-AI content (Socially Responsible HE book); these chunks have ai_score=0 and are excluded from full_v1 anyway.
A24: 23 | B24: =FALSE() -> FALSE | F24: Why do Brazilian higher education institutions differ so much and why do the students who access them face unequal conditions? | G24: The historical evolution of Brazil's national higher education system was marked by structuring inequalities in the country's economic, social and cultural formation. These inequalities were decisive in the complexity and heterogeneity of institutions and in the inequality of the students who accessed that level of schooling. | H24: Higher education in Brazil began late, compared to other Latin American countries. The establishment of the first university, the University of Brazil, dates back to 1920. The historical evolution of the national system of higher education was marked by the structuring inequalities in Brazil's economic, social and cultural formation, which were decisive in the complexity and heterogeneity of institutions and in the inequality of the students who accessed that level of schooling. | I24: Socially Responsible Higher Education, p. 50 | J24: =TRUE() -> TRUE | K24: =FALSE() -> FALSE | M24: explanation | N24: medium | O24: equity_accessibility | P24: 5 | Q24: 3 | R24: Both sentences of the answer directly restate the evidence's claim that structuring inequalities in Brazil's economic, social and cultural formation shaped institutional heterogeneity and student inequality. | The question names Brazil and higher education explicitly and does not refer to any unseen source. | value: This is institutional context for higher education, but it is narrow and not specifically about AI. | S24: What historical factor made Brazil's higher education institutions complex and heterogeneous and its students unequal? | T24: How did Brazil's historical formation lead to institutional heterogeneity and unequal student access in higher education? | U24: pilot | V24: budd-l-hall-rajesh-2021-socially-responsible:0027:q2 | W24: accept | Y24: Non-AI content (Socially Responsible HE book); these chunks have ai_score=0 and are excluded from full_v1 anyway.
A25: 24 | B25: =FALSE() -> FALSE | F25: How are Brazilian higher education institutions divided between public and private types? | G25: Public institutions (federal, state or municipal) belong to the state, and registration in them is free of charge, as determined by the Federal Constitution of 1988. Private institutions may be for-profit or non-profit, or even denominational. | H25: Public institutions (federal, state or municipal) belong to the state, and registrations to it are free of charge, as determined in the Federal Constitution of 1988, while private institutions may be for-profit or non-profit (or even denominational). | I25: Socially Responsible Higher Education, p. 50 | J25: =TRUE() -> TRUE | K25: =FALSE() -> FALSE | M25: definition | N25: easy | O25: general | P25: 5 | Q25: 3 | R25: Every statement in the answer is directly stated in the evidence: public types, free enrollment under the 1988 Constitution, and the private for-profit, non-profit and denominational types. | The question names Brazil and the topic explicitly and does not depend on any unseen source. | value: This is institutional context relevant to higher education, but it is narrow and not about AI. | S25: What are the categories of public and private higher education institutions in Brazil? | T25: In Brazil, how is the higher education sector split between public and private institutions? | U25: pilot | V25: budd-l-hall-rajesh-2021-socially-responsible:0027:q3 | W25: accept | Y25: Non-AI content (Socially Responsible HE book); these chunks have ai_score=0 and are excluded from full_v1 anyway.
A26: 25 | B26: =FALSE() -> FALSE | F26: What does Article 130 of Peru's Law 30220 require every university to create? | G26: Article 130 obliges every Peruvian university to create a University Social Service Programme (Programa de Servicio Social Universitario). Through it, students apply knowledge in a way that improves the quality of life of people in traditionally marginalised groups. | H26: Article 130 establishes the obligation to implement SRHEI. Per this article, every university should create a Programa de Servicio Social Universitario (University Social Service Programme), through which students apply knowledge in a way that improves the quality of life of people in traditionally marginalised groups. | I26: Socially Responsible Higher Education, p. 220 | J26: =TRUE() -> TRUE | K26: =FALSE() -> FALSE | M26: factual | N26: easy | O26: governance | P26: 4 | Q26: 3 | R26: The answer restates the evidence closely; 'obliges' slightly strengthens the evidence's 'should', which is trivial given the article establishes an obligation. | The question names the specific law and article and does not rely on unseen context. | value: This is a narrow, country-specific legal detail about university social responsibility, not about AI directly. | S26: Under Article 130 of Peru's Law 30220, what programme must each university set up? | T26: Which programme does Article 130 of Peruvian Law 30220 oblige all universities to implement? | U26: pilot | V26: budd-l-hall-rajesh-2021-socially-responsible:0118:q0 | W26: accept | Y26: Non-AI content (Socially Responsible HE book); these chunks have ai_score=0 and are excluded from full_v1 anyway.
A27: 26 | B27: =FALSE() -> FALSE | F27: What did a 2018 study by the Latin American Social Responsibility in Higher Education Union (URSULA) find about how Peruvian universities executed socially responsible initiatives? | G27: A 2018 study by the Latin American Social Responsibility in Higher Education Union (URSULA) found that all 18 Peruvian universities surveyed had difficulty executing socially responsible initiatives, with results below the regional average. | H27: In fact, a 2018 study by Unión de Responsabilidad Social Universitaria Latinoamericana - URSULA (Latin American Social Responsibility in Higher Education Union) found that all 18 Peruvian universities surveyed had difficulty in executing socially responsible initiatives, with results below the regional average (p. 17). | I27: Socially Responsible Higher Education, p. 220 | J27: =TRUE() -> TRUE | K27: =TRUE() -> TRUE | M27: factual | N27: easy | O27: leadership_strategy | P27: 5 | Q27: 3 | R27: The answer restates the evidence exactly: all 18 Peruvian universities surveyed had difficulty, with results below the regional average. | The question names the specific study and organization by its content, so it is clear without the source. | value: It is a narrow, region-specific finding about university social responsibility and is only tangentially about AI. | S27: What were the findings of the 2018 Latin American Social Responsibility in Higher Education Union (URSULA) study on Peruvian universities' execution of socially responsible initiatives? | T27: What was the finding of the Latin American Social Responsibility in Higher Education Union (URSULA) in its 2018 study regarding the way Peruvian universities carried out socially responsible initiatives? | U27: pilot | V27: budd-l-hall-rajesh-2021-socially-responsible:0118:q2 | W27: accept | Y27: Non-AI content (Socially Responsible HE book); these chunks have ai_score=0 and are excluded from full_v1 anyway.
A28: 27 | B28: =FALSE() -> FALSE | F28: A Peruvian university plans to meet its legal duties under Law 30220 only by managing the impact of its operations, as in Article 124. Would this satisfy the Act, given the principles and obligations in Articles 5, 6 and 130? | G28: Scholars analysing Law 30220 posit that the Act obliges all universities to construct all their programmes with a social responsibility component. They argue that a university focusing strictly on managing impact, as per Article 124 read on its own, would not be compliant with the principles and obligations set out in Articles 5, 6 and 130. Articles 5 and 6 make pluralism, inclusion, intercultural dialogue and commitment to the country's development guiding principles, and Article 130 obliges every university to create a University Social Service Programme. | H28: Taking the values set out in Articles 5 and 6 as a starting point, we posit that the Act in fact obliges all universities to construct all their programmes with a social responsibility component. This because if a university were to focus strictly on managing impact, as per article 124 of the Act read on its own, it would not be compliant of the principles and obligations set out in Articles 5, 6 and 130. … Articles 5 and 6 establish that pluralism, inclusion, intercultural dialogue and commitment to the country's development are the guiding principles of higher education, and universities should strive to interact with the community and engage in socially relevant teaching and research. … Article 130 establishes the obligation to implement SRHEI. Per this article, every university should create a Programa de Servicio Social Universitario (University Social Service Programme), through which students apply knowledge in a way that improves the quality of life of people in traditionally marginalised groups. | I28: Socially Responsible Higher Education, pp. 219-220 | J28: =TRUE() -> TRUE | K28: =TRUE() -> TRUE | M28: application | N28: hard | O28: governance | P28: 5 | Q28: 4 | R28: Every statement in the answer is directly stated in the evidence. This covers the claim that all programmes need a social responsibility component, the non-compliance of a strict impact-management approach, the guiding principles in Articles 5 and 6, and the University Social Service Programme required by Article 130. | The question names Law 30220 and the specific articles. It is understandable without having seen the source. | value: This is useful but somewhat jurisdiction-specific knowledge about how Peruvian law frames university social responsibility. | S28: If a university in Peru focuses strictly on impact management under Article 124 of Law 30220, would that comply with the Act's principles and obligations in Articles 5, 6 and 130? | T28: Would a Peruvian university that relies solely on managing its impact per Article 124 of Law 30220 be compliant, considering Articles 5, 6 and 130? | U28: pilot | V28: budd-l-hall-rajesh-2021-socially-responsible:0118:q3 | W28: accept | Y28: Non-AI content (Socially Responsible HE book); these chunks have ai_score=0 and are excluded from full_v1 anyway.
A29: 28 | B29: =FALSE() -> FALSE | F29: Why has implementation of the social responsibility obligations in Peru's Law 30220 been uneven and difficult? | G29: This may be due in large part to the lack of further regulations, policies or government-sponsored programmes accompanying the Act. Universities without the necessary expertise or resources to create or enhance such programmes received no state-sponsored support. | H29: However, the obligations set out in the Act have had a disparate and difficult implementation. This may be due in large part to the lack of further regulations, policies or government sponsored programmes to accompany the Act. Where universities did not have the necessary expertise or resources to create or enhance SRHEI programmes within their institutions, there was no statesponsored support for their implementation. | I29: Socially Responsible Higher Education, p. 220 | J29: =TRUE() -> TRUE | K29: =FALSE() -> FALSE | M29: factual | N29: easy | O29: leadership_strategy | P29: 4 | Q29: 3 | R29: The answer restates the evidence closely, with only minor rewording (e.g., 'such programmes' for SRHEI programmes). | The question names Peru's Law 30220 and its social responsibility obligations explicitly and does not rely on any unseen source. | value: University social responsibility policy is relevant institutional context, but this is a narrow, country-specific point that is not about AI. | S29: What is the main suggested reason for the disparate and difficult implementation of Law 30220's social responsibility obligations in Peru? | T29: Why have Peruvian universities struggled to implement the social responsibility duties set by Law 30220? | U29: pilot | V29: budd-l-hall-rajesh-2021-socially-responsible:0118:q4 | W29: accept | Y29: Non-AI content (Socially Responsible HE book); these chunks have ai_score=0 and are excluded from full_v1 anyway.
A30: 29 | B30: =FALSE() -> FALSE | F30: How are the top 300 universities in the Times Higher Education World University Rankings distributed geographically? | G30: Of the purportedly top 300 universities, 270 (90%) are located in Europe, North America, Australia and New Zealand. Of the remainder, 25 are from a small number of East Asian countries and only 5 are from the rest of the world. The entire continent of Africa is represented by three institutions, all in South Africa, and there is only one university from the whole of Latin America, one from the Middle East, and none from Central Asia. | H30: Taking the Times Higher Education (THE) World University Rankings (THE, 2020) as an example, of the purportedly 'top 300' universities in the world, 270 (90%) are located in Europe, North America, Australia and New Zealand. Of the remainder, 25 are from a small number of East Asian countries and there are only 5 from the rest of the world. … The entire continent of Africa is represented by three institutions, all of which are in South Africa. There is only one university from the whole of Latin America, one from the Middle East, and not a single institution from Central Asia. | I30: Socially Responsible Higher Education, p. 95 | J30: =TRUE() -> TRUE | K30: =TRUE() -> TRUE | M30: definition | N30: medium | O30: equity_accessibility | P30: 5 | Q30: 3 | R30: Every figure and claim in the answer is stated directly in the evidence, with only minor rewording. | The question names the specific ranking explicitly and needs no other context, though it omits the 2020 edition year. | value: It illustrates global inequity in higher education rankings, which is relevant context but a fairly specific data point. | S30: What does the geographic distribution of the top 300 universities in the Times Higher Education World University Rankings look like? | T30: In the Times Higher Education World University Rankings, where are the top 300 universities located? | U30: pilot | V30: budd-l-hall-rajesh-2021-socially-responsible:0055:q0 | W30: accept | Y30: Non-AI content (Socially Responsible HE book); these chunks have ai_score=0 and are excluded from full_v1 anyway.
A31: 30 | B31: =FALSE() -> FALSE | F31: A university leader in Nairobi is told that global rankings are a neutral measure of quality and that their institution should simply accept its absence from the top. What do the Times Higher Education rankings' geographic patterns and the message they imply say about this claim? | G31: In the Times Higher Education rankings, the whole of Africa is represented by only three institutions, all in South Africa, and the ARWU and QS rankings are only a few percentage points more geographically inclusive. The message these rankings send is that 'world class' status, quality or excellence are highly concentrated in specific places and, by implication, not present in others. | H31: The entire continent of Africa is represented by three institutions, all of which are in South Africa. There is only one university from the whole of Latin America, one from the Middle East, and not a single institution from Central Asia. … THE is not alone in this bias - the Academic Ranking of World Universities (ARWU, 2019) and QS World University Rankings (QS, 2019) are more geographically inclusive, but only by a few percentage points. … The message seems clear - 'world class' status, 'quality', or 'excellence' are highly concentrated in specific places. It is therefore, by implication, not present in others. | I31: Socially Responsible Higher Education, pp. 95-96 | J31: =TRUE() -> TRUE | K31: =FALSE() -> FALSE | M31: application | N31: hard | O31: equity_accessibility | P31: 4 | Q31: 4 | R31: Every statement is in the evidence. Tying the Africa count to Times Higher Education specifically is inferred from 'THE is not alone in this bias' rather than stated outright. | The scenario is self-contained and names the Times Higher Education rankings explicitly, with no reference to an unseen source. | value: It covers a useful critique of geographic bias in global university rankings and its implications for institutions outside the top. | S31: A Kenyan university leader hears that world rankings neutrally measure quality and that being absent from the top is just a fact. What do the geographic patterns of the Times Higher Education rankings and their implied message say about it? | T31: A Nairobi university leader hears that global rankings objectively measure quality and that the institution should just accept not being near the top. What do the geographic patterns in the Times Higher Education rankings, and the message they imply, say about that claim? | U31: pilot | V31: budd-l-hall-rajesh-2021-socially-responsible:0055:q1 | W31: accept | Y31: Non-AI content (Socially Responsible HE book); these chunks have ai_score=0 and are excluded from full_v1 anyway.
